Workbook

Sheet ENTRADA_GAMS
B1: region | C1: mes | D1: Vreq_m3 | F1: region | G1: LimSub_m3 | H1: LimSup_m3 | J1: region | K1: mes | L1: P_mm | M1: Pef_mm | O1: region | P1: Area_ha | R1: region | S1: AreaProd_ha | T1: Prod_ton
A2: 0 | B2: Uruapan | C2: Ene | D2: 7731677.3 | F2: Uruapan | G2: 17466017 | H2: 54297077 | J2: Uruapan | K2: Ene | L2: 39.6 | M2: 37.090944 | O2: Uruapan | P2: 11879 | R2: Uruapan | S2: 11731 | T2: 135683.22
A3: 1 | B3: Uruapan | C3: Feb | D3: 14142724 | F3: Tancitaro | G3: 11373791 | H3: 7800166.9 | J3: Uruapan | K3: Feb | L3: 7.7 | M3: 7.605136 | O3: Tancitaro | P3: 3865 | R3: Tancitaro | S3: 3830 | T3: 43555.6
A4: 2 | B4: Uruapan | C4: Mar | D4: 19886725 | F4: Periban | G4: 8001509.5 | H4: 21476525 | J4: Uruapan | K4: Mar | L4: 3.6 | M4: 3.579264 | O4: Periban | P4: 2876 | R4: Periban | S4: 2862 | T4: 34748.56
A5: 3 | B5: Uruapan | C5: Abr | D5: 20662791 | F5: Ario | G5: 7247764.3 | H5: 66967720 | J5: Uruapan | K5: Abr | L5: 10 | M5: 9.84 | O5: Ario | P5: 8302 | R5: Ario | S5: 8231 | T5: 98500
A6: 4 | B6: Uruapan | C6: May | D6: 15682299 | F6: SalvadorEscalante | G6: 8540375.3 | H6: 19505419 | J6: Uruapan | K6: May | L6: 33.5 | M6: 31.7044 | O6: SalvadorEscalante | P6: 8246 | R6: SalvadorEscalante | S6: 8155 | T6: 103731.6
A7: 5 | B7: Uruapan | C7: Jun | D7: 0 | F7: Tacambaro | G7: 7183648.2 | H7: 95863552 | J7: Uruapan | K7: Jun | L7: 273.6 | M7: 152.36 | O7: Tacambaro | P7: 10333 | R7: Tacambaro | S7: 10145 | T7: 140026.5
A8: 6 | B8: Uruapan | C8: Jul | D8: 0 | J8: Uruapan | K8: Jul | L8: 321.9 | M8: 157.19
A9: 7 | B9: Uruapan | C9: Ago | D9: 0 | J9: Uruapan | K9: Ago | L9: 326.9 | M9: 157.69
A10: 8 | B10: Uruapan | C10: Sep | D10: 0 | J10: Uruapan | K10: Sep | L10: 285.5 | M10: 153.55
A11: 9 | B11: Uruapan | C11: Oct | D11: 0 | J11: Uruapan | K11: Oct | L11: 135.9 | M11: 106.3499
A12: 10 | B12: Uruapan | C12: Nov | D12: 8325855.3 | J12: Uruapan | K12: Nov | L12: 31 | M12: 29.4624
A13: 11 | B13: Uruapan | C13: Dic | D13: 11303477 | J13: Uruapan | K13: Dic | L13: 11.8 | M13: 11.577216
A14: 12 | B14: Tancitaro | C14: Ene | D14: 2947294.4 | J14: Tancitaro | K14: Ene | L14: 26.5 | M14: 25.3764
A15: 13 | B15: Tancitaro | C15: Feb | D15: 4124722.5 | J15: Tancitaro | K15: Feb | L15: 13 | M15: 12.7296
A16: 14 | B16: Tancitaro | C16: Mar | D16: 5600610.5 | J16: Tancitaro | K16: Mar | L16: 15.7 | M16: 15.305616
A17: 15 | B17: Tancitaro | C17: Abr | D17: 6944524 | J17: Tancitaro | K17: Abr | L17: 2.2 | M17: 2.192256
A18: 16 | B18: Tancitaro | C18: May | D18: 3264191.1 | J18: Tancitaro | K18: May | L18: 70.9 | M18: 62.857104
A19: 17 | B19: Tancitaro | C19: Jun | D19: 0 | J19: Tancitaro | K19: Jun | L19: 300.6 | M19: 155.06
... A73: 71 | B73: Tacambaro | C73: Dic | D73: 10618956 | J73: Tacambaro | K73: Dic | L73: 5.7 | M73: 5.648016

Sheet ETO_GAMS
A1: region | B1: mes | C1: ET0_mm
A2: Uruapan | B2: Ene | C2: 94.300445
A3: Uruapan | B3: Feb | C3: 105.00679
A4: Uruapan | B4: Mar | C4: 139.64057
A5: Uruapan | B5: Abr | C5: 152.7381
A6: Uruapan | B6: May | C6: 149.68835
A7: Uruapan | B7: Jun | C7: 116.02489
A8: Uruapan | B8: Jul | C8: 112.2452
A9: Uruapan | B9: Ago | C9: 108.88109
A10: Uruapan | B10: Sep | C10: 95.28312
A11: Uruapan | B11: Oct | C11: 95.834661
A12: Uruapan | B12: Nov | C12: 88.161471
A13: Uruapan | B13: Dic | C13: 86.886058
... A73: Tacambaro | B73: Dic | C73: 91.398798

Sheet KC_EFECTIVO
A1: region | B1: mes | C1: Kc_efectivo_ET0
A2: Uruapan | B2: Ene | C2: 0.68911833
A3: Uruapan | B3: Feb | C3: 0.6
A4: Uruapan | B4: Mar | C4: 0.6
A5: Uruapan | B5: Abr | C5: 0.69262784
A6: Uruapan | B6: May | C6: 0.85
A7: Uruapan | B7: Jun | C7: 0.85
A8: Uruapan | B8: Jul | C8: 0.85
A9: Uruapan | B9: Ago | C9: 0.85
A10: Uruapan | B10: Sep | C10: 0.85
A11: Uruapan | B11: Oct | C11: 0.85
A12: Uruapan | B12: Nov | C12: 0.81720876
A13: Uruapan | B13: Dic | C13: 0.75
... A73: Tacambaro | B73: Dic | C73: 0.75

Sheet ETC_GAMS
A1: region | B1: mes | C1: ETc_mm
A2: Uruapan | B2: Ene | C2: 64.984165
A3: Uruapan | B3: Feb | C3: 63.004071
A4: Uruapan | B4: Mar | C4: 83.78434
A5: Uruapan | B5: Abr | C5: 105.79066
A6: Uruapan | B6: May | C6: 127.2351
A7: Uruapan | B7: Jun | C7: 98.621159
A8: Uruapan | B8: Jul | C8: 95.408423
A9: Uruapan | B9: Ago | C9: 92.548929
A10: Uruapan | B10: Sep | C10: 80.990652
A11: Uruapan | B11: Oct | C11: 81.459462
A12: Uruapan | B12: Nov | C12: 72.046327
A13: Uruapan | B13: Dic | C13: 65.164543
... A73: Tacambaro | B73: Dic | C73: 68.549098

Sheet CALENDARIO
A1: Fecha representativa | B1: Día del año | C1: Mes | D1: Kc diario E1
A2: 2001-01-01 | B2: 1 | C2: Ene | D2: 0.75
A3: 2001-01-02 | B3: 2 | C3: Ene | D3: 0.75
A4: 2001-01-03 | B4: 3 | C4: Ene | D4: 0.75
A5: 2001-01-04 | B5: 4 | C5: Ene | D5: 0.75
A6: 2001-01-05 | B6: 5 | C6: Ene | D6: 0.75
A7: 2001-01-06 | B7: 6 | C7: Ene | D7: 0.75
A8: 2001-01-07 | B8: 7 | C8: Ene | D8: 0.75
A9: 2001-01-08 | B9: 8 | C9: Ene | D9: 0.75
A10: 2001-01-09 | B10: 9 | C10: Ene | D10: 0.75
A11: 2001-01-10 | B11: 10 | C11: Ene | D11: 0.75
A12: 2001-01-11 | B12: 11 | C12: Ene | D12: 0.75
A13: 2001-01-12 | B13: 12 | C13: Ene | D13: 0.75
... A366: 2001-12-31 | B366: 365 | C366: Dic | D366: 0.75

Sheet CONTROL
A1: Región | B1: Mes | C1: ET0 mm | D1: Kc efectivo | E1: ETc base mm | F1: ETc=ET0×Kc | G1: Residuo ETc mm | H1: Pef mm | I1: Área ha
A2: =ETO_GAMS!A2 -> Uruapan | B2: =ETO_GAMS!B2 -> Ene | C2: =ETO_GAMS!C2 -> 94.300445 | D2: =KC_EFECTIVO!C2 -> 0.68911833 | E2: =ETC_GAMS!C2 -> 64.984165 | F2: =C2*D2 -> 64.984165 | G2: =E2-F2 -> 0 | H2: =ENTRADA_GAMS!M2 -> 37.090944 | I2: =ENTRADA_GAMS!P2 -> 11879
A3: =ETO_GAMS!A3 -> Uruapan | B3: =ETO_GAMS!B3 -> Feb | C3: =ETO_GAMS!C3 -> 105.00679 | D3: =KC_EFECTIVO!C3 -> 0.6 | E3: =ETC_GAMS!C3 -> 63.004071 | F3: =C3*D3 -> 63.004071 | G3: =E3-F3 -> 0 | H3: =ENTRADA_GAMS!M3 -> 7.605136 | I3: =ENTRADA_GAMS!P2 -> 11879
A4: =ETO_GAMS!A4 -> Uruapan | B4: =ETO_GAMS!B4 -> Mar | C4: =ETO_GAMS!C4 -> 139.64057 | D4: =KC_EFECTIVO!C4 -> 0.6 | E4: =ETC_GAMS!C4 -> 83.78434 | F4: =C4*D4 -> 83.78434 | G4: =E4-F4 -> 0 | H4: =ENTRADA_GAMS!M4 -> 3.579264 | I4: =ENTRADA_GAMS!P2 -> 11879
A5: =ETO_GAMS!A5 -> Uruapan | B5: =ETO_GAMS!B5 -> Abr | C5: =ETO_GAMS!C5 -> 152.7381 | D5: =KC_EFECTIVO!C5 -> 0.69262784 | E5: =ETC_GAMS!C5 -> 105.79066 | F5: =C5*D5 -> 105.79066 | G5: =E5-F5 -> 0 | H5: =ENTRADA_GAMS!M5 -> 9.84 | I5: =ENTRADA_GAMS!P2 -> 11879
A6: =ETO_GAMS!A6 -> Uruapan | B6: =ETO_GAMS!B6 -> May | C6: =ETO_GAMS!C6 -> 149.68835 | D6: =KC_EFECTIVO!C6 -> 0.85 | E6: =ETC_GAMS!C6 -> 127.2351 | F6: =C6*D6 -> 127.2351 | G6: =E6-F6 -> 0 | H6: =ENTRADA_GAMS!M6 -> 31.7044 | I6: =ENTRADA_GAMS!P2 -> 11879
A7: =ETO_GAMS!A7 -> Uruapan | B7: =ETO_GAMS!B7 -> Jun | C7: =ETO_GAMS!C7 -> 116.02489 | D7: =KC_EFECTIVO!C7 -> 0.85 | E7: =ETC_GAMS!C7 -> 98.621159 | F7: =C7*D7 -> 98.621159 | G7: =E7-F7 -> 0 | H7: =ENTRADA_GAMS!M7 -> 152.36 | I7: =ENTRADA_GAMS!P2 -> 11879
A8: =ETO_GAMS!A8 -> Uruapan | B8: =ETO_GAMS!B8 -> Jul | C8: =ETO_GAMS!C8 -> 112.2452 | D8: =KC_EFECTIVO!C8 -> 0.85 | E8: =ETC_GAMS!C8 -> 95.408423 | F8: =C8*D8 -> 95.408423 | G8: =E8-F8 -> 0 | H8: =ENTRADA_GAMS!M8 -> 157.19 | I8: =ENTRADA_GAMS!P2 -> 11879
A9: =ETO_GAMS!A9 -> Uruapan | B9: =ETO_GAMS!B9 -> Ago | C9: =ETO_GAMS!C9 -> 108.88109 | D9: =KC_EFECTIVO!C9 -> 0.85 | E9: =ETC_GAMS!C9 -> 92.548929 | F9: =C9*D9 -> 92.548929 | G9: =E9-F9 -> 0 | H9: =ENTRADA_GAMS!M9 -> 157.69 | I9: =ENTRADA_GAMS!P2 -> 11879
A10: =ETO_GAMS!A10 -> Uruapan | B10: =ETO_GAMS!B10 -> Sep | C10: =ETO_GAMS!C10 -> 95.28312 | D10: =KC_EFECTIVO!C10 -> 0.85 | E10: =ETC_GAMS!C10 -> 80.990652 | F10: =C10*D10 -> 80.990652 | G10: =E10-F10 -> 0 | H10: =ENTRADA_GAMS!M10 -> 153.55 | I10: =ENTRADA_GAMS!P2 -> 11879
A11: =ETO_GAMS!A11 -> Uruapan | B11: =ETO_GAMS!B11 -> Oct | C11: =ETO_GAMS!C11 -> 95.834661 | D11: =KC_EFECTIVO!C11 -> 0.85 | E11: =ETC_GAMS!C11 -> 81.459462 | F11: =C11*D11 -> 81.459462 | G11: =E11-F11 -> 0 | H11: =ENTRADA_GAMS!M11 -> 106.3499 | I11: =ENTRADA_GAMS!P2 -> 11879
A12: =ETO_GAMS!A12 -> Uruapan | B12: =ETO_GAMS!B12 -> Nov | C12: =ETO_GAMS!C12 -> 88.161471 | D12: =KC_EFECTIVO!C12 -> 0.81720876 | E12: =ETC_GAMS!C12 -> 72.046327 | F12: =C12*D12 -> 72.046327 | G12: =E12-F12 -> 0 | H12: =ENTRADA_GAMS!M12 -> 29.4624 | I12: =ENTRADA_GAMS!P2 -> 11879
A13: =ETO_GAMS!A13 -> Uruapan | B13: =ETO_GAMS!B13 -> Dic | C13: =ETO_GAMS!C13 -> 86.886058 | D13: =KC_EFECTIVO!C13 -> 0.75 | E13: =ETC_GAMS!C13 -> 65.164543 | F13: =C13*D13 -> 65.164543 | G13: =E13-F13 -> 0 | H13: =ENTRADA_GAMS!M13 -> 11.577216 | I13: =ENTRADA_GAMS!P2 -> 11879
A14: =ETO_GAMS!A14 -> Tancitaro | B14: =ETO_GAMS!B14 -> Ene | C14: =ETO_GAMS!C14 -> 92.664027 | D14: =KC_EFECTIVO!C14 -> 0.68875576 | E14: =ETC_GAMS!C14 -> 63.822883 | F14: =C14*D14 -> 63.822883 | G14: =E14-F14 -> 0 | H14: =ENTRADA_GAMS!M14 -> 25.3764 | I14: =ENTRADA_GAMS!P3 -> 3865
A15: =ETO_GAMS!A15 -> Tancitaro | B15: =ETO_GAMS!B15 -> Feb | C15: =ETO_GAMS!C15 -> 104.34341 | D15: =KC_EFECTIVO!C15 -> 0.6 | E15: =ETC_GAMS!C15 -> 62.606046 | F15: =C15*D15 -> 62.606046 | G15: =E15-F15 -> 0 | H15: =ENTRADA_GAMS!M15 -> 12.7296 | I15: =ENTRADA_GAMS!P3 -> 3865
A16: =ETO_GAMS!A16 -> Tancitaro | B16: =ETO_GAMS!B16 -> Mar | C16: =ETO_GAMS!C16 -> 139.77255 | D16: =KC_EFECTIVO!C16 -> 0.6 | E16: =ETC_GAMS!C16 -> 83.863532 | F16: =C16*D16 -> 83.863532 | G16: =E16-F16 -> 0 | H16: =ENTRADA_GAMS!M16 -> 15.305616 | I16: =ENTRADA_GAMS!P3 -> 3865
A17: =ETO_GAMS!A17 -> Tancitaro | B17: =ETO_GAMS!B17 -> Abr | C17: =ETO_GAMS!C17 -> 153.70517 | D17: =KC_EFECTIVO!C17 -> 0.69297103 | E17: =ETC_GAMS!C17 -> 106.51323 | F17: =C17*D17 -> 106.51323 | G17: =E17-F17 -> 0 | H17: =ENTRADA_GAMS!M17 -> 2.192256 | I17: =ENTRADA_GAMS!P3 -> 3865
A18: =ETO_GAMS!A18 -> Tancitaro | B18: =ETO_GAMS!B18 -> May | C18: =ETO_GAMS!C18 -> 151.51825 | D18: =KC_EFECTIVO!C18 -> 0.85 | E18: =ETC_GAMS!C18 -> 128.79052 | F18: =C18*D18 -> 128.79052 | G18: =E18-F18 -> 0 | H18: =ENTRADA_GAMS!M18 -> 62.857104 | I18: =ENTRADA_GAMS!P3 -> 3865
A19: =ETO_GAMS!A19 -> Tancitaro | B19: =ETO_GAMS!B19 -> Jun | C19: =ETO_GAMS!C19 -> 114.80358 | D19: =KC_EFECTIVO!C19 -> 0.85 | E19: =ETC_GAMS!C19 -> 97.583044 | F19: =C19*D19 -> 97.583044 | G19: =E19-F19 -> 0 | H19: =ENTRADA_GAMS!M19 -> 155.06 | I19: =ENTRADA_GAMS!P3 -> 3865
A20: =ETO_GAMS!A20 -> Tancitaro | B20: =ETO_GAMS!B20 -> Jul | C20: =ETO_GAMS!C20 -> 110.8553 | D20: =KC_EFECTIVO!C20 -> 0.85 | E20: =ETC_GAMS!C20 -> 94.227001 | F20: =C20*D20 -> 94.227001 | G20: =E20-F20 -> 0 | H20: =ENTRADA_GAMS!M20 -> 153.54 | I20: =ENTRADA_GAMS!P3 -> 3865
A21: =ETO_GAMS!A21 -> Tancitaro | B21: =ETO_GAMS!B21 -> Ago | C21: =ETO_GAMS!C21 -> 106.46388 | D21: =KC_EFECTIVO!C21 -> 0.85 | E21: =ETC_GAMS!C21 -> 90.494297 | F21: =C21*D21 -> 90.494297 | G21: =E21-F21 -> 0 | H21: =ENTRADA_GAMS!M21 -> 154.97 | I21: =ENTRADA_GAMS!P3 -> 3865
A22: =ETO_GAMS!A22 -> Tancitaro | B22: =ETO_GAMS!B22 -> Sep | C22: =ETO_GAMS!C22 -> 92.488262 | D22: =KC_EFECTIVO!C22 -> 0.85 | E22: =ETC_GAMS!C22 -> 78.615023 | F22: =C22*D22 -> 78.615023 | G22: =E22-F22 -> 0 | H22: =ENTRADA_GAMS!M22 -> 156.79 | I22: =ENTRADA_GAMS!P3 -> 3865
A23: =ETO_GAMS!A23 -> Tancitaro | B23: =ETO_GAMS!B23 -> Oct | C23: =ETO_GAMS!C23 -> 92.674632 | D23: =KC_EFECTIVO!C23 -> 0.85 | E23: =ETC_GAMS!C23 -> 78.773437 | F23: =C23*D23 -> 78.773437 | G23: =E23-F23 -> 0 | H23: =ENTRADA_GAMS!M23 -> 138.9444 | I23: =ENTRADA_GAMS!P3 -> 3865
A24: =ETO_GAMS!A24 -> Tancitaro | B24: =ETO_GAMS!B24 -> Nov | C24: =ETO_GAMS!C24 -> 85.476028 | D24: =KC_EFECTIVO!C24 -> 0.81719614 | E24: =ETC_GAMS!C24 -> 69.85068 | F24: =C24*D24 -> 69.85068 | G24: =E24-F24 -> 0 | H24: =ENTRADA_GAMS!M24 -> 51.719824 | I24: =ENTRADA_GAMS!P3 -> 3865
A25: =ETO_GAMS!A25 -> Tancitaro | B25: =ETO_GAMS!B25 -> Dic | C25: =ETO_GAMS!C25 -> 84.6021 | D25: =KC_EFECTIVO!C25 -> 0.75 | E25: =ETC_GAMS!C25 -> 63.451575 | F25: =C25*D25 -> 63.451575 | G25: =E25-F25 -> 0 | H25: =ENTRADA_GAMS!M25 -> 10.613376 | I25: =ENTRADA_GAMS!P3 -> 3865
A26: =ETO_GAMS!A26 -> Periban | B26: =ETO_GAMS!B26 -> Ene | C26: =ETO_GAMS!C26 -> 102.85694 | D26: =KC_EFECTIVO!C26 -> 0.68872821 | E26: =ETC_GAMS!C26 -> 70.840477 | F26: =C26*D26 -> 70.840477 | G26: =E26-F26 -> 0 | H26: =ENTRADA_GAMS!M26 -> 19.640656 | I26: =ENTRADA_GAMS!P4 -> 2876
A27: =ETO_GAMS!A27 -> Periban | B27: =ETO_GAMS!B27 -> Feb | C27: =ETO_GAMS!C27 -> 115.28301 | D27: =KC_EFECTIVO!C27 -> 0.6 | E27: =ETC_GAMS!C27 -> 69.169809 | F27: =C27*D27 -> 69.169809 | G27: =E27-F27 -> 0 | H27: =ENTRADA_GAMS!M27 -> 6.040464 | I27: =ENTRADA_GAMS!P4 -> 2876
A28: =ETO_GAMS!A28 -> Periban | B28: =ETO_GAMS!B28 -> Mar | C28: =ETO_GAMS!C28 -> 152.10669 | D28: =KC_EFECTIVO!C28 -> 0.6 | E28: =ETC_GAMS!C28 -> 91.264012 | F28: =C28*D28 -> 91.264012 | G28: =E28-F28 -> 0 | H28: =ENTRADA_GAMS!M28 -> 4.073104 | I28: =ENTRADA_GAMS!P4 -> 2876
A29: =ETO_GAMS!A29 -> Periban | B29: =ETO_GAMS!B29 -> Abr | C29: =ETO_GAMS!C29 -> 163.91362 | D29: =KC_EFECTIVO!C29 -> 0.69230452 | E29: =ETC_GAMS!C29 -> 113.47814 | F29: =C29*D29 -> 113.47814 | G29: =E29-F29 -> 0 | H29: =ENTRADA_GAMS!M29 -> 2.49 | I29: =ENTRADA_GAMS!P4 -> 2876
A30: =ETO_GAMS!A30 -> Periban | B30: =ETO_GAMS!B30 -> May | C30: =ETO_GAMS!C30 -> 157.5243 | D30: =KC_EFECTIVO!C30 -> 0.85 | E30: =ETC_GAMS!C30 -> 133.89565 | F30: =C30*D30 -> 133.89565 | G30: =E30-F30 -> 0 | H30: =ENTRADA_GAMS!M30 -> 29.101824 | I30: =ENTRADA_GAMS!P4 -> 2876
A31: =ETO_GAMS!A31 -> Periban | B31: =ETO_GAMS!B31 -> Jun | C31: =ETO_GAMS!C31 -> 116.17532 | D31: =KC_EFECTIVO!C31 -> 0.85 | E31: =ETC_GAMS!C31 -> 98.749023 | F31: =C31*D31 -> 98.749023 | G31: =E31-F31 -> 0 | H31: =ENTRADA_GAMS!M31 -> 150.66 | I31: =ENTRADA_GAMS!P4 -> 2876
A32: =ETO_GAMS!A32 -> Periban | B32: =ETO_GAMS!B32 -> Jul | C32: =ETO_GAMS!C32 -> 110.45697 | D32: =KC_EFECTIVO!C32 -> 0.85 | E32: =ETC_GAMS!C32 -> 93.888422 | F32: =C32*D32 -> 93.888422 | G32: =E32-F32 -> 0 | H32: =ENTRADA_GAMS!M32 -> 155.78 | I32: =ENTRADA_GAMS!P4 -> 2876
A33: =ETO_GAMS!A33 -> Periban | B33: =ETO_GAMS!B33 -> Ago | C33: =ETO_GAMS!C33 -> 105.91205 | D33: =KC_EFECTIVO!C33 -> 0.85 | E33: =ETC_GAMS!C33 -> 90.02524 | F33: =C33*D33 -> 90.02524 | G33: =E33-F33 -> 0 | H33: =ENTRADA_GAMS!M33 -> 158.09 | I33: =ENTRADA_GAMS!P4 -> 2876
A34: =ETO_GAMS!A34 -> Periban | B34: =ETO_GAMS!B34 -> Sep | C34: =ETO_GAMS!C34 -> 92.62525 | D34: =KC_EFECTIVO!C34 -> 0.85 | E34: =ETC_GAMS!C34 -> 78.731462 | F34: =C34*D34 -> 78.731462 | G34: =E34-F34 -> 0 | H34: =ENTRADA_GAMS!M34 -> 151.62 | I34: =ENTRADA_GAMS!P4 -> 2876
A35: =ETO_GAMS!A35 -> Periban | B35: =ETO_GAMS!B35 -> Oct | C35: =ETO_GAMS!C35 -> 94.876104 | D35: =KC_EFECTIVO!C35 -> 0.85 | E35: =ETC_GAMS!C35 -> 80.644688 | F35: =C35*D35 -> 80.644688 | G35: =E35-F35 -> 0 | H35: =ENTRADA_GAMS!M35 -> 109.08058 | I35: =ENTRADA_GAMS!P4 -> 2876
A36: =ETO_GAMS!A36 -> Periban | B36: =ETO_GAMS!B36 -> Nov | C36: =ETO_GAMS!C36 -> 90.258986 | D36: =KC_EFECTIVO!C36 -> 0.81674684 | E36: =ETC_GAMS!C36 -> 73.718742 | F36: =C36*D36 -> 73.718742 | G36: =E36-F36 -> 0 | H36: =ENTRADA_GAMS!M36 -> 29.0116 | I36: =ENTRADA_GAMS!P4 -> 2876
A37: =ETO_GAMS!A37 -> Periban | B37: =ETO_GAMS!B37 -> Dic | C37: =ETO_GAMS!C37 -> 92.493719 | D37: =KC_EFECTIVO!C37 -> 0.75 | E37: =ETC_GAMS!C37 -> 69.370289 | F37: =C37*D37 -> 69.370289 | G37: =E37-F37 -> 0 | H37: =ENTRADA_GAMS!M37 -> 8.578896 | I37: =ENTRADA_GAMS!P4 -> 2876
A38: =ETO_GAMS!A38 -> Ario | B38: =ETO_GAMS!B38 -> Ene | C38: =ETO_GAMS!C38 -> 98.107923 | D38: =KC_EFECTIVO!C38 -> 0.68891553 | E38: =ETC_GAMS!C38 -> 67.588073 | F38: =C38*D38 -> 67.588073 | G38: =E38-F38 -> 0 | H38: =ENTRADA_GAMS!M38 -> 24.367744 | I38: =ENTRADA_GAMS!P5 -> 8302
A39: =ETO_GAMS!A39 -> Ario | B39: =ETO_GAMS!B39 -> Feb | C39: =ETO_GAMS!C39 -> 109.57253 | D39: =KC_EFECTIVO!C39 -> 0.6 | E39: =ETC_GAMS!C39 -> 65.743518 | F39: =C39*D39 -> 65.743518 | G39: =E39-F39 -> 0 | H39: =ENTRADA_GAMS!M39 -> 4.073104 | I39: =ENTRADA_GAMS!P5 -> 8302
A40: =ETO_GAMS!A40 -> Ario | B40: =ETO_GAMS!B40 -> Mar | C40: =ETO_GAMS!C40 -> 145.4289 | D40: =KC_EFECTIVO!C40 -> 0.6 | E40: =ETC_GAMS!C40 -> 87.257342 | F40: =C40*D40 -> 87.257342 | G40: =E40-F40 -> 0 | H40: =ENTRADA_GAMS!M40 -> 3.9744 | I40: =ENTRADA_GAMS!P5 -> 8302
...
